<mujoco model="x2">
  <option gravity="0 0 -9.81" />
  <option integrator="RK4">
    <flag energy="enable"/>
  </option>
  <compiler angle="radian" />
  <visual>
    <headlight diffuse="0.6 0.6 0.6" ambient="0.1 0.1 0.1" specular="0.9 0.9 0.9"/>
    <rgba haze="0.15 0.25 0.35 1"/>
    <global azimuth="140" elevation="-20"/>
  </visual>
  <asset>
    <texture type="skybox" builtin="gradient" rgb1="0.3 0.5 0.7" rgb2="0 0 0" width="512" height="3072"/>
    <texture type="2d" name="groundplane" builtin="checker" mark="edge" rgb1="0.2 0.3 0.4" rgb2="0.1 0.2 0.3"
      markrgb="0.8 0.8 0.8" width="300" height="300"/>
    <material name="groundplane" texture="groundplane" texuniform="true" texrepeat="5 5" reflectance="0.2"/>
  </asset>
  <actuator>
    <motor name="left_hip_joint_motor" joint="left_hip_joint" ctrlrange="-1000 1000" ctrllimited="true" />
    <motor name="left_knee_joint_motor" joint="left_knee_joint" ctrlrange="-1000 1000" ctrllimited="true" />
    <!-- Define more actuators for other joints as needed -->
  </actuator>
  <asset>
    <mesh name="back_pack" file="back_pack.stl" scale="0.001 0.001 0.001" />
    <mesh name="hip_sa" file="hip_sa.stl" scale="0.001 0.001 0.001" />
    <mesh name="thigh-l_s" file="thigh-l_s.stl" scale="0.001 0.001 0.001" />
    <mesh name="knee-l" file="knee-l.stl" scale="0.001 0.001 0.001" />
    <mesh name="shank-l" file="shank-l.stl" scale="0.001 0.001 0.001" />
    <mesh name="ankle" file="ankle.stl" scale="0.001 0.001 0.001" />
    <mesh name="foot-l" file="foot-l.stl" scale="0.001 0.001 0.001" />
    <mesh name="hip-r" file="hip-r.stl" scale="0.001 0.001 0.001" />
    <mesh name="thigh-r" file="thigh-r.stl" scale="0.001 0.001 0.001" />
    <mesh name="knee-r" file="knee-r.stl" scale="0.001 0.001 0.001" />
    <mesh name="shank-r" file="shank-r.stl" scale="0.001 0.001 0.001" />
    <mesh name="foot-r" file="foot-r.stl" scale="0.001 0.001 0.001" />
  </asset>
  <worldbody>
    <geom name="floor" pos="0 0 -0.5" size="0 0 0.05" type="plane" material="groundplane"/>
    <body name="backpack" pos="0 0 1.05" quat="0.5 0.5 0.5 0.5">
      <inertial pos="0.00139519 -0.0708429 0.0143736" quat="0.155308 0.69016 0.160036 0.688438" mass="8.063" diaginertia="0.275688 0.187219 0.144619" />
      <joint name="world_to_backpack" pos="0 0 0" axis="-1 0 0" range="-1.5708 1.5708" actuatorfrcrange="-40 40" damping="1" frictionloss="2" />
      <geom type="mesh" contype="1" conaffinity="1" group="1" density="0" mesh="back_pack" />
      <geom pos="0.191605 -0.211166 0.13831" quat="0 0 0.707107 0.707107" type="mesh" contype="1" conaffinity="1" group="1" density="0" mesh="hip_sa" />
      <geom pos="-0.191605 -0.211166 0.13831" quat="0.707107 -0.707107 0 0" type="mesh" contype="1" conaffinity="1" group="1" density="0" mesh="hip-r" />
      <body name="left_upper_thigh" pos="0.182275 -0.211166 0.13831" quat="-1 0 0 0">
        <inertial pos="-0.0044319 -0.254625 0.000368545" quat="0.713939 0.671779 -0.127372 0.150933" mass="2.1844" diaginertia="0.0398119 0.0387337 0.00242996" />
        <joint name="left_hip_joint" type="hinge" pos="0 0 0" axis="-1 0 0" range="-0.698132 2.0944" actuatorfrcrange="-80 80" damping="2" frictionloss="2" />
        <geom type="mesh" contype="1" conaffinity="1" group="1" density="0" mesh="thigh-l_s" />
        <geom pos="-0.00313 -0.37 0" quat="0 0 1 0" type="mesh" contype="1" conaffinity="1" group="1" density="0" mesh="knee-l" />
        <body name="left_upper_thigh_drive_inertia">
          <inertial pos="0 0 0" mass="0.1" diaginertia="0.0001246 0.0001 0.0001" />
          <joint name="left_hip_joint_drive" type="hinge" pos="0 0 0" axis="1 0 0" actuatorfrcrange="-0.3265 0.3265" />
        </body>
        <body name="left_upper_shank" pos="-0.01687 -0.37 0" quat="0 0 1 0">
          <!-- <site name="s1" pos="0.15 0.06 0" size="0.02"/> -->
          <site name="knee_l" pos="0.01 0 0" size="0.005" rgba="0 .7 0 1"/>
          <site name="cuff_side" pos="0.02 -0.1 0" size="0.005" rgba="0 .7 0 1"/>
          <site name="cuff_front" pos="0.07 -0.1 -0.07" size="0.005" rgba="0 .7 0 1"/>
          <site name="feet_pad_center" pos="0.07 -0.4688 0" type = "box" size="0.02 0.005 0.02" rgba=".7 0 0 1"/>
          <site name="feet_pad1" pos="0.03 -0.4688 0" size="0.005" rgba="0 .7 0 1"/>
          <site name="feet_pad2" pos="0.11 -0.4688 0" size="0.005" rgba="0 .7 0 1"/>
          <site name="feet_pad3" pos="0.07 -0.4688 0.04" size="0.005" rgba="0 0 1 1"/>
          <site name="feet_pad4" pos="0.07 -0.4688 -0.04" size="0.005" rgba="0 0 1 1"/>
          <inertial pos="0.0271111 -0.312012 -0.0161233" quat="0.493497 0.558098 -0.454237 0.488524" mass="1.6105" diaginertia="0.0594614 0.0591666 0.0118376" />
          <joint name="left_knee_joint" type="hinge" pos="0 0 0" axis="1 0 0" range="-2.0944 0" actuatorfrcrange="-80 80" damping="2" frictionloss="2" />
          <geom name="left_shank" type="mesh" contype="1" conaffinity="1" group="1" density="0" mesh="shank-l" />
          <geom pos="-0.006 -0.36 0" quat="0.707107 -0.707107 0 0" type="mesh" contype="1" conaffinity="1" group="1" density="0" mesh="ankle" />
          <geom pos="-0.006 -0.36 0" quat="0.707107 -0.707107 0 0" type="mesh" contype="1" conaffinity="1" group="1" density="0" mesh="foot-l" />
          <body name="left_upper_shank_drive_inertia">
            <inertial pos="0 0 0" mass="0.1" diaginertia="0.0001246 0.0001 0.0001" />
            <joint name="left_knee_joint_drive" type="hinge" pos="0 0 0" axis="1 0 0" actuatorfrcrange="-0.3265 0.3265" />
          </body>
        </body>
      </body>
      <body name="right_upper_thigh" pos="-0.182275 -0.211166 0.13831" quat="0 0 1 0">
        <inertial pos="-0.0044319 -0.254625 -0.000368545" quat="0.671779 0.713939 0.150933 -0.127372" mass="2.1844" diaginertia="0.0398119 0.0387337 0.00242996" />
        <joint name="right_hip_joint" type="hinge" pos="0 0 0" axis="1 0 0" range="-0.698132 2.0944" actuatorfrcrange="-80 80" damping="2" frictionloss="2" />
        <geom type="mesh" contype="1" conaffinity="1" group="1" density="0" mesh="thigh-r" />
        <geom pos="-0.00313 -0.37 0" quat="0 0 1 0" type="mesh" contype="1" conaffinity="1" group="1" density="0" mesh="knee-r" />
        <body name="right_upper_thigh_drive_inertia">
          <inertial pos="0 0 0" mass="0.1" diaginertia="0.0001246 0.0001 0.0001" />
          <joint name="right_hip_joint_drive" type="hinge" pos="0 0 0" axis="-1 0 0" actuatorfrcrange="-0.3265 0.3265" />
        </body>
        <body name="right_upper_shank" pos="-0.01687 -0.37 0" quat="0 0 1 0">
          <inertial pos="0.0271111 -0.312012 0.0161233" quat="0.454237 0.488524 -0.493497 0.558098" mass="1.6105" diaginertia="0.0594614 0.0591666 0.0118376" />
          <joint name="right_knee_joint" type="hinge" pos="0 0 0" axis="-1 0 0" range="-2.0944 0" actuatorfrcrange="-80 80" damping="2" frictionloss="2" />
          <geom type="mesh" contype="1" conaffinity="1" group="1" density="0" mesh="shank-r" />
          <geom pos="-0.006 -0.36 0" quat="0.707107 -0.707107 0 0" type="mesh" contype="1" conaffinity="1" group="1" density="0" mesh="ankle" />
          <geom pos="-0.006 -0.36 0" quat="0.707107 -0.707107 0 0" type="mesh" contype="1" conaffinity="1" group="1" density="0" mesh="foot-r" />
          <body name="right_upper_shank_drive_inertia">
            <inertial pos="0 0 0" mass="0.1" diaginertia="0.0001246 0.0001 0.0001" />
            <joint name="right_knee_joint_drive" type="hinge" pos="0 0 0" axis="-1 0 0" actuatorfrcrange="-0.3265 0.3265" />
          </body>
        </body>
      </body>
    </body>
    <body name="left_human_shank" pos="0.1381 0.09 0.2344" quat = "0.5  0. 0. 0.">

      <site name="human_knee_top" pos="0 0.04 0.2344" size="0.005" rgba="0 0 0.8 1"/>
      <site name="human_knee_btm1" pos="0 0.04 -0.2344" size="0.005" rgba="0 0 0.8 1"/>
      <site name="human_knee_btm2" pos="0 -0.04 -0.2344" size="0.005" rgba="0 0.8 0.8 1"/>
      <site name="human_knee_btm3" pos="-0.04 0 -0.2344" size="0.005" rgba="0.8 0 0 1"/>
      <site name="human_knee_btm4" pos="0.04 0 -0.2344" size="0.005" rgba="0.8 0.5 0 1"/>
      <site name="human_knee_btm_center" pos="0 0 -0.2344" type = "box" size="0.02 0.02 0.001"  rgba="0 1 0 1"/>
      <site name="human_knee_sidecuff" pos="0 0.04 0.1344" size="0.005" rgba="0 0 0.8 1"/>
      <site name="human_knee_frontcuff" pos="0.04 0 0.1344" size="0.005" rgba="0 0 0.8 1"/>
      <site name ="ss_cuff_side" pos="0 0.0395 0.1344" size="0.005" rgba="1 0 0 1"/>
      <site name="ss_cuff_front" pos="0.0395 0.0 0.1344" size="0.005" rgba="1 0 0 1"/>
      <joint name="human_knee_joint" type="hinge" axis="0 -1 0" pos="0 0 0.2344" damping="2" frictionloss="2" />
      <geom name="left_human_shank" type="cylinder" size="0.04 0.2344" rgba="1 0.75 0.8 0.2" contype="1" conaffinity="1" />
      <inertial pos="0 0 0" mass="0.001" diaginertia="0.1 0.1 0.1" />
      <!-- <body name="left_human_upper_thigh" pos="0.0 0.0 0.4688" quat="0 0 1 0">
        <geom name="left_human_upper_thigh" type="cylinder" size="0.04 0.2" rgba="0 0.8 0.8 0.5" contype="1" conaffinity="1" />
      </body> -->
      <body name="sensor_site" pos="0 0 -0.2344">
        <site name="feetsensor" pos="0 0 0" rgba="0 0 1 1" type="box" size="0.02 0.02 0.001"/>
      </body>
    </body>
  </worldbody>
  <actuator>
    <motor name="human_knee_actuator" joint="human_knee_joint" ctrlrange="-50 50" ctrllimited="true" />
  </actuator>


  <tendon>
    <spatial name="knee_connection_side" limited="true" range="0 0.05" width="0.003" stiffness="1500" damping="10">
      <site site="human_knee_sidecuff"/>

      <site site="cuff_side"/>
    </spatial>
  </tendon>

  <tendon>
    <spatial name="knee_connection_front" limited="true" range="0 0.05" width="0.003" stiffness="1500" damping="10">
      <site site="human_knee_frontcuff"/>

      <site site="cuff_front"/>
    </spatial>
  </tendon> 


  <equality>
    <weld body1="left_human_shank" body2 = "left_upper_shank" solimp="0.9 0.95 0.001" solref="0.005 1" anchor="0 0 -0.2344"/>
  </equality>


  <!-- <tendon>
    <spatial name="feet_connection_center" width="0.009" stiffness="200000" damping="10">
      <site site="human_knee_btm_center"/>
      <geom geom="left_human_shank"/>
      <site site="feet_pad_center"/>
    </spatial>
  </tendon> -->

  <sensor>
      <!-- tendon's lenth will be sensed -->
      <!-- <tendonlimitpos tendon="knee_connection_front" /> -->
      <!-- tendon's velocity will be sensed  -->
      <!-- <tendonlimitvel tendon="knee_connection_front" />
      <tendonlimitfrc tendon="knee_connection_front" /> -->
      <force site="feetsensor" />
  </sensor>

  <!-- <tendon>
    <spatial name="feet_connection1"  range="0 .0001" width="0.005" stiffness="20000" damping="5000">
      <site site="human_knee_btm1"/>
      <geom geom="left_human_shank"/>
      <site site="feet_pad1"/>
    </spatial>
  </tendon>

  <tendon>
    <spatial name="feet_connection2" range="0 .0001" width="0.005" stiffness="20000" damping="5000">
      <site site="human_knee_btm2"/>
      <geom geom="left_human_shank"/>
      <site site="feet_pad2"/>
    </spatial>
  </tendon> -->

  <!-- <tendon>
    <spatial name="feet_connection3" range="0 .0001" width="0.005" stiffness="20000" damping="5000">
      <site site="human_knee_btm3"/>
      <geom geom="left_human_shank"/>
      <site site="feet_pad3"/>
    </spatial>
  </tendon>

  <tendon>
    <spatial name="feet_connection4" range="0 .0001" width="0.005" stiffness="20000" damping="5000">
      <site site="human_knee_btm4"/>
      <geom geom="left_human_shank"/>
      <site site="feet_pad4"/>
    </spatial>
  </tendon> -->

</mujoco>
