<mujoco model="x2">
  <option gravity = "0 0 -9.81" />
  <compiler angle="radian"/>
  <actuator>
    <motor name="left_hip_joint_motor" joint="left_hip_joint" ctrlrange="-30 30" ctrllimited="true"/>
  </actuator>
  <actuator>
    <motor name="left_knee_joint_motor" joint="left_knee_joint" ctrlrange="-30 30" ctrllimited="true"/>
    <!-- Define more actuators for other joints as needed -->
  </actuator>
  <asset>
    <mesh name="back_pack" file="back_pack.stl" scale="0.001 0.001 0.001"/>
    <mesh name="hip_sa" file="hip_sa.stl" scale="0.001 0.001 0.001"/>
    <mesh name="thigh-l_s" file="thigh-l_s.stl" scale="0.001 0.001 0.001"/>
    <mesh name="knee-l" file="knee-l.stl" scale="0.001 0.001 0.001"/>
    <mesh name="shank-l" file="shank-l.stl" scale="0.001 0.001 0.001"/>
    <mesh name="ankle" file="ankle.stl" scale="0.001 0.001 0.001"/>
    <mesh name="foot-l" file="foot-l.stl" scale="0.001 0.001 0.001"/>
    <mesh name="hip-r" file="hip-r.stl" scale="0.001 0.001 0.001"/>
    <mesh name="thigh-r" file="thigh-r.stl" scale="0.001 0.001 0.001"/>
    <mesh name="knee-r" file="knee-r.stl" scale="0.001 0.001 0.001"/>
    <mesh name="shank-r" file="shank-r.stl" scale="0.001 0.001 0.001"/>
    <mesh name="foot-r" file="foot-r.stl" scale="0.001 0.001 0.001"/>
  </asset>
  <worldbody>
    <body name="backpack" pos="0 0 1.05" quat="0.5 0.5 0.5 0.5">
      <inertial pos="0.00139519 -0.0708429 0.0143736" quat="0.155308 0.69016 0.160036 0.688438" mass="8.063" diaginertia="0.275688 0.187219 0.144619"/>
      <joint name="world_to_backpack" pos="0 0 0" axis="-1 0 0" range="-1.5708 1.5708" actuatorfrcrange="-40 40" damping="1" frictionloss="2"/>
      <geom type="mesh" contype="0" conaffinity="0" group="1" density="0" mesh="back_pack"/>
      <geom pos="0.191605 -0.211166 0.13831" quat="0 0 0.707107 0.707107" type="mesh" contype="0" conaffinity="0" group="1" density="0" mesh="hip_sa"/>
      <geom pos="-0.191605 -0.211166 0.13831" quat="0.707107 -0.707107 0 0" type="mesh" contype="0" conaffinity="0" group="1" density="0" mesh="hip-r"/>
      <body name="left_upper_thigh" pos="0.182275 -0.211166 0.13831" quat="-1 0 0 0">
        <inertial pos="-0.0044319 -0.254625 0.000368545" quat="0.713939 0.671779 -0.127372 0.150933" mass="2.1844" diaginertia="0.0398119 0.0387337 0.00242996"/>
        <joint name="left_hip_joint" type="hinge" pos="0 0 0" axis="-1 0 0" range="-0.698132 2.0944" actuatorfrcrange="-80 80" damping="2" frictionloss="2"/>
        <geom type="mesh" contype="0" conaffinity="0" group="1" density="0" mesh="thigh-l_s"/>
        <geom pos="-0.00313 -0.37 0" quat="0 0 1 0" type="mesh" contype="0" conaffinity="0" group="1" density="0" mesh="knee-l"/>
        <body name="left_upper_thigh_drive_inertia">
          <inertial pos="0 0 0" mass="0.1" diaginertia="0.0001246 0.0001 0.0001"/>
          <joint name="left_hip_joint_drive" type="hinge" pos="0 0 0" axis="1 0 0" actuatorfrcrange="-0.3265 0.3265"/>
        </body>
        <body name="left_upper_shank" pos="-0.01687 -0.37 0" quat="0 0 1 0">
          <inertial pos="0.0271111 -0.312012 -0.0161233" quat="0.493497 0.558098 -0.454237 0.488524" mass="1.6105" diaginertia="0.0594614 0.0591666 0.0118376"/>
          <joint name="left_knee_joint" type="hinge" pos="0 0 0" axis="1 0 0" range="-2.0944 0" actuatorfrcrange="-80 80" damping="2" frictionloss="2"/>
          <geom type="mesh" contype="0" conaffinity="0" group="1" density="0" mesh="shank-l"/>
          <geom pos="-0.006 -0.36 0" quat="0.707107 -0.707107 0 0" type="mesh" contype="0" conaffinity="0" group="1" density="0" mesh="ankle"/>
          <geom pos="-0.006 -0.36 0" quat="0.707107 -0.707107 0 0" type="mesh" contype="0" conaffinity="0" group="1" density="0" mesh="foot-l"/>
          <body name="left_upper_shank_drive_inertia">
            <inertial pos="0 0 0" mass="0.1" diaginertia="0.0001246 0.0001 0.0001"/>
            <joint name="left_knee_joint_drive" type="hinge" pos="0 0 0" axis="1 0 0" actuatorfrcrange="-0.3265 0.3265"/>
          </body>
        </body>
      </body>
      <body name="right_upper_thigh" pos="-0.182275 -0.211166 0.13831" quat="0 0 1 0">
        <inertial pos="-0.0044319 -0.254625 -0.000368545" quat="0.671779 0.713939 0.150933 -0.127372" mass="2.1844" diaginertia="0.0398119 0.0387337 0.00242996"/>
        <joint name="right_hip_joint" type="hinge" pos="0 0 0" axis="1 0 0" range="-0.698132 2.0944" actuatorfrcrange="-80 80" damping="2" frictionloss="2"/>
        <geom type="mesh" contype="0" conaffinity="0" group="1" density="0" mesh="thigh-r"/>
        <geom pos="-0.00313 -0.37 0" quat="0 0 1 0" type="mesh" contype="0" conaffinity="0" group="1" density="0" mesh="knee-r"/>
        <body name="right_upper_thigh_drive_inertia">
          <inertial pos="0 0 0" mass="0.1" diaginertia="0.0001246 0.0001 0.0001"/>
          <joint name="right_hip_joint_drive" type="hinge" pos="0 0 0" axis="-1 0 0" actuatorfrcrange="-0.3265 0.3265"/>
        </body>
        <body name="right_upper_shank" pos="-0.01687 -0.37 0" quat="0 0 1 0">
          <inertial pos="0.0271111 -0.312012 0.0161233" quat="0.454237 0.488524 -0.493497 0.558098" mass="1.6105" diaginertia="0.0594614 0.0591666 0.0118376"/>
          <joint name="right_knee_joint" type="hinge" pos="0 0 0" axis="-1 0 0" range="-2.0944 0" actuatorfrcrange="-80 80" damping="2" frictionloss="2"/>
          <geom type="mesh" contype="0" conaffinity="0" group="1" density="0" mesh="shank-r"/>
          <geom pos="-0.006 -0.36 0" quat="0.707107 -0.707107 0 0" type="mesh" contype="0" conaffinity="0" group="1" density="0" mesh="ankle"/>
          <geom pos="-0.006 -0.36 0" quat="0.707107 -0.707107 0 0" type="mesh" contype="0" conaffinity="0" group="1" density="0" mesh="foot-r"/>
          <body name="right_upper_shank_drive_inertia">
            <inertial pos="0 0 0" mass="0.1" diaginertia="0.0001246 0.0001 0.0001"/>
            <joint name="right_knee_joint_drive" type="hinge" pos="0 0 0" axis="-1 0 0" actuatorfrcrange="-0.3265 0.3265"/>
          </body>
        </body>
      </body>
    </body>
  </worldbody>
</mujoco>
