<?xml version="1.0" ?>
<!-- =================================================================================== -->
<!-- |    This document was autogenerated by xacro from x2_fixed_base.urdf.xacro       | -->
<!-- |    EDITING THIS FILE BY HAND IS NOT RECOMMENDED                                 | -->
<!-- =================================================================================== -->
<robot name="x2">
  <mujoco>
    <compiler meshdir="" balanceinertia="true" discardvisual="false"/>
  </mujoco>
  <!-- [m] This is the distance between the hips. This doesn't equal to the value written on the adjustable link on the real hardware. There is an offset between that value and distance between the hips. I don,t know what the value written on the real link correspond to -->
  <!-- [kg * m^2] -->
  <!-- [m] -->
  <!-- [kg * m^2] -->
  <!-- [rad] -->
  <!-- [kg * m^2] -->
  <!-- [rad] -->
  <!-- [kg * m^2] -->
  <!-- [kg * m^2] -->
  <!-- [Nm] effort limit-->
  <!-- static friction [Nm] NOT CORRECT VALUE -->
  <!-- static friction [Nm] NOT CORRECT VALUE -->
  <!-- static friction [Nm] NOT CORRECT VALUE -->
  <link name="world">
</link>
  <link name="backpack">
    <!-- <visual>
    <origin xyz="0 0.15 0" rpy="0 0 0"/>
    <geometry>
    <box size="0.5 0.5 0.15" />
    </geometry>
     <material name="red_mat">
         <color rgba="1 0 0 0.5" />
     </material>
  </visual> -->
    <visual>
      <origin rpy="0 0 0" xyz="0 0 0"/>
      <geometry>
        <mesh filename="package://turtle_brick/back_pack.stl" scale="0.001   0.001   0.001"/>
      </geometry>
    </visual>
    <inertial>
      <origin rpy="0 0 0" xyz="0.002445 -0.0006 -0.0322"/>
      <mass value="4.601"/>
      <inertia ixx="0.03978" ixy="0.0005696" ixz="-0.0002889" iyy="0.03754" iyz="-0.0004189" izz="0.06294"/>
    </inertial>
  </link>
  <joint name="world_to_backpack" type="revolute">
    <parent link="world"/>
    <child link="backpack"/>
    <origin rpy="1.5707963267948966 0.0 1.5707963267948966" xyz="0.0 0.0 1.05"/>
    <axis xyz="-1 0 0"/>
    <limit effort="40.0" lower="-1.5707963267948966" upper="1.5707963267948966" velocity="3.0"/>
    <dynamics damping="1.0" friction="2.0"/>
  </joint>
  <!-- Transmission tags for ros control -->
  <transmission name="{joint_name}_transmission">
    <type>transmission_interface/SimpleTransmission</type>
    <joint name="world_to_backpack">
      <hardwareInterface>hardware_interface/PositionJointInterface</hardwareInterface>
    </joint>
    <actuator name="world_to_backpack_actuator">
      <hardwareInterface>hardware_interface/PositionJointInterface</hardwareInterface>
      <mechanicalReduction>1</mechanicalReduction>
    </actuator>
  </transmission>
  <link name="left_hip_extension">
    <visual>
      <origin rpy="0 0 0" xyz="0 0 0"/>
      <geometry>
        <mesh filename="package://turtle_brick/hip_sa.stl" scale="0.001   0.001   0.001"/>
      </geometry>
    </visual>
    <inertial>
      <origin rpy="0 0 0" xyz="0.00981 -0.06204 0.04697"/>
      <mass value="1.731"/>
      <inertia ixx="0.02033" ixy="-0.002197" ixz="0.001336" iyy="0.007419" iyz="-0.007508" izz="0.01534"/>
    </inertial>
  </link>
  <joint name="fixed_backpack_to_left_hip_ext" type="fixed">
    <parent link="backpack"/>
    <child link="left_hip_extension"/>
    <origin rpy="1.5707963267948966 0.0 3.141592653589793" xyz="0.191605 -0.21116568396859933 0.13831"/>
  </joint>
  <link name="left_upper_thigh">
    <visual>
      <origin rpy="0 0 0" xyz="0 0 0"/>
      <geometry>
        <mesh filename="package://turtle_brick/thigh-l_s.stl" scale="0.001   0.001   0.001"/>
      </geometry>
    </visual>
    <inertial>
      <origin rpy="0 0 0" xyz="-0.00833 -0.0811 -0.0105"/>
      <mass value="0.5594"/>
      <inertia ixx="0.005943" ixy="0.0003468" ixz="0.0003781" iyy="0.001062" iyz="0.000558" izz="0.005716"/>
    </inertial>
  </link>
  <joint name="left_hip_joint" type="revolute">
    <parent link="left_hip_extension"/>
    <child link="left_upper_thigh"/>
    <origin rpy="1.5707963267948966 0.0 3.141592653589793" xyz="0.00933 0.0 0.0"/>
    <axis xyz="-1 0 0"/>
    <limit effort="80.0" lower="-0.6981317007977318" upper="2.0943951023931953" velocity="3.0"/>
    <dynamics damping="2.0" friction="2.0"/>
  </joint>
  <!-- Fixed joint to add dummy inertia link -->
  <joint name="left_hip_joint_drive" type="continuous">
    <parent link="left_upper_thigh"/>
    <child link="left_upper_thigh_drive_inertia"/>
    <origin rpy="0 0 0" xyz="0 0 0"/>
    <axis xyz="1 0 0"/>
    <limit effort="0.3265" velocity="367.5"/>
    <mimic joint="left_hip_joint" multiplier="0.0081632653"/>
  </joint>
  <visual>
    <origin rpy="0.0 0.0 0.0" xyz="0.0 0.0 0.0"/>
    <geometry>
      <box size="0.1 0.1 0.1"/>
    </geometry>
    <material name="red_mat">
      <color rgba="1 0 0 0.5"/>
    </material>
  </visual>
  <!-- Dummy inertia link, because KDL cannot have inertia on the base link -->
  <link name="left_upper_thigh_drive_inertia">
    <inertial>
      <origin rpy="0 0 0" xyz="0.0 0.0 0.0"/>
      <mass value="0.1"/>
      <inertia ixx="0.0001246" ixy="0.0" ixz="0.0" iyy="0.0001" iyz="0.0" izz="0.0001"/>
    </inertial>
  </link>
  <!-- Transmission tags for ros control -->
  <transmission name="{joint_name}_transmission">
    <type>transmission_interface/SimpleTransmission</type>
    <joint name="left_hip_joint">
      <hardwareInterface>hardware_interface/EffortJointInterface</hardwareInterface>
      <hardwareInterface>hardware_interface/PositionJointInterface</hardwareInterface>
      <hardwareInterface>hardware_interface/VelocityJointInterface</hardwareInterface>
    </joint>
    <actuator name="left_hip_joint_actuator">
      <hardwareInterface>hardware_interface/EffortJointInterface</hardwareInterface>
      <hardwareInterface>hardware_interface/PositionJointInterface</hardwareInterface>
      <hardwareInterface>hardware_interface/VelocityJointInterface</hardwareInterface>
      <mechanicalReduction>1</mechanicalReduction>
    </actuator>
  </transmission>
  <link name="left_upper_thigh_sensor"/>
  <joint name="left_upper_thigh_to_left_upper_thigh_sensor" type="fixed">
    <parent link="left_upper_thigh"/>
    <child link="left_upper_thigh_sensor"/>
    <origin rpy="0.0 0.0 0.0" xyz="-0.00369 -0.085 0.0"/>
  </joint>
  <link name="left_lower_thigh">
    <visual>
      <origin rpy="0 0 0" xyz="0 0 0"/>
      <geometry>
        <mesh filename="package://turtle_brick/knee-l.stl" scale="0.001   0.001   0.001"/>
      </geometry>
    </visual>
    <inertial>
      <origin rpy="0 0 0" xyz="-4e-05 0.05564 -0.00411"/>
      <mass value="1.625"/>
      <inertia ixx="0.01096" ixy="5.38e-05" ixz="-1.32e-05" iyy="0.001439" iyz="-0.0003957" izz="0.01037"/>
    </inertial>
  </link>
  <joint name="fixed_left_upper_thigh_to_lower_thigh" type="fixed">
    <parent link="left_upper_thigh"/>
    <child link="left_lower_thigh"/>
    <origin rpy="0.0 3.141592653589793 0.0" xyz="-0.00313 -0.37 0.0"/>
  </joint>
  <link name="left_upper_shank">
    <visual>
      <origin rpy="0 0 0" xyz="0 0 0"/>
      <geometry>
        <mesh filename="package://turtle_brick/shank-l.stl" scale="0.001   0.001   0.001"/>
      </geometry>
    </visual>
    <inertial>
      <origin rpy="0 0 0" xyz="0.007566 -0.0908 -0.00799"/>
      <mass value="0.5008"/>
      <inertia ixx="0.006507" ixy="-0.0003135" ixz="-0.0002377" iyy="0.0007056" iyz="0.0004257" izz="0.006426"/>
    </inertial>
  </link>
  <joint name="left_knee_joint" type="revolute">
    <parent link="left_lower_thigh"/>
    <child link="left_upper_shank"/>
    <origin rpy="0.0 0.0 0.0" xyz="0.01374 0.0 0.0"/>
    <axis xyz="1 0 0"/>
    <limit effort="80.0" lower="-2.0943951023931953" upper="0.0" velocity="12.566370614359172"/>
    <dynamics damping="2.0" friction="2.0"/>
  </joint>
  <!-- Fixed joint to add dummy inertia link -->
  <joint name="left_knee_joint_drive" type="continuous">
    <parent link="left_upper_shank"/>
    <child link="left_upper_shank_drive_inertia"/>
    <origin rpy="0 0 0" xyz="0 0 0"/>
    <axis xyz="1 0 0"/>
    <limit effort="0.3265" velocity="367.5"/>
    <mimic joint="left_knee_joint" multiplier="0.0081632653"/>
  </joint>
  <visual>
    <origin rpy="0.0 0.0 0.0" xyz="0.0 0.0 0.0"/>
    <geometry>
      <box size="0.1 0.1 0.1"/>
    </geometry>
    <material name="red_mat">
      <color rgba="1 0 0 0.5"/>
    </material>
  </visual>
  <!-- Dummy inertia link, because KDL cannot have inertia on the base link -->
  <link name="left_upper_shank_drive_inertia">
    <inertial>
      <origin rpy="0 0 0" xyz="0.0 0.0 0.0"/>
      <mass value="0.1"/>
      <inertia ixx="0.0001246" ixy="0.0" ixz="0.0" iyy="0.0001" iyz="0.0" izz="0.0001"/>
    </inertial>
  </link>
  <!-- Transmission tags for ros control -->
  <transmission name="{joint_name}_transmission">
    <type>transmission_interface/SimpleTransmission</type>
    <joint name="left_knee_joint">
      <hardwareInterface>hardware_interface/EffortJointInterface</hardwareInterface>
      <hardwareInterface>hardware_interface/PositionJointInterface</hardwareInterface>
      <hardwareInterface>hardware_interface/VelocityJointInterface</hardwareInterface>
    </joint>
    <actuator name="left_knee_joint_actuator">
      <hardwareInterface>hardware_interface/EffortJointInterface</hardwareInterface>
      <hardwareInterface>hardware_interface/PositionJointInterface</hardwareInterface>
      <hardwareInterface>hardware_interface/VelocityJointInterface</hardwareInterface>
      <mechanicalReduction>1</mechanicalReduction>
    </actuator>
  </transmission>
  <link name="left_upper_shank_sensor"/>
  <joint name="left_upper_shank_to_left_upper_shank_sensor" type="fixed">
    <parent link="left_upper_shank"/>
    <child link="left_upper_shank_sensor"/>
    <origin rpy="0.0 0.0 0.0" xyz="0.0019 -0.1 0.0"/>
  </joint>
  <link name="left_lower_shank">
    <visual>
      <origin rpy="0 0 0" xyz="0 0 0"/>
      <geometry>
        <mesh filename="package://turtle_brick/ankle.stl" scale="0.001   0.001   0.001"/>
      </geometry>
    </visual>
    <inertial>
      <origin rpy="0 0 0" xyz="-0.0009 0.0 0.0562"/>
      <mass value="0.2802"/>
      <inertia ixx="0.001679" ixy="0.0" ixz="0.0" iyy="0.001662" iyz="0.0" izz="7.45e-05"/>
    </inertial>
  </link>
  <joint name="fixed_left_upper_shank_to_lower_shank" type="fixed">
    <parent link="left_upper_shank"/>
    <child link="left_lower_shank"/>
    <origin rpy="-1.5707963267948966 0.0 0.0" xyz="-0.006 -0.36 0.0"/>
  </joint>
  <link name="left_foot">
    <visual>
      <origin rpy="0 0 0" xyz="0 0 0"/>
      <geometry>
        <mesh filename="package://turtle_brick/foot-l.stl" scale="0.001   0.001   0.001"/>
      </geometry>
    </visual>
    <inertial>
      <origin rpy="0 0 0" xyz="0.0564 0.02648 -0.08834"/>
      <mass value="0.8295"/>
      <inertia ixx="0.01149" ixy="0.001746" ixz="-0.004842" iyy="0.01179" iyz="-0.002451" izz="0.007927"/>
    </inertial>
  </link>
  <joint name="fixed_left_lower_shank_to_foot" type="fixed">
    <parent link="left_lower_shank"/>
    <child link="left_foot"/>
    <origin rpy="0.0 0.0 0.0" xyz="0.0 0.0 0.0"/>
  </joint>
  <link name="right_hip_extension">
    <visual>
      <origin rpy="0 0 0" xyz="0 0 0"/>
      <geometry>
        <mesh filename="package://turtle_brick/hip-r.stl" scale="0.001   0.001   0.001"/>
      </geometry>
    </visual>
    <inertial>
      <origin rpy="0 0 0" xyz="0.00981 0.06204 0.04697"/>
      <mass value="1.731"/>
      <inertia ixx="0.02033" ixy="0.002197" ixz="0.001336" iyy="0.007419" iyz="0.007508" izz="0.01534"/>
    </inertial>
  </link>
  <joint name="fixed_backpack_to_right_hip_ext" type="fixed">
    <parent link="backpack"/>
    <child link="right_hip_extension"/>
    <origin rpy="4.71238898038469 0.0 6.283185307179586" xyz="-0.191605 -0.21116568396859933 0.13831"/>
  </joint>
  <link name="right_upper_thigh">
    <visual>
      <origin rpy="0 0 0" xyz="0 0 0"/>
      <geometry>
        <mesh filename="package://turtle_brick/thigh-r.stl" scale="0.001   0.001   0.001"/>
      </geometry>
    </visual>
    <inertial>
      <origin rpy="0 0 0" xyz="-0.00833 -0.0811 0.0105"/>
      <mass value="0.5594"/>
      <inertia ixx="0.005943" ixy="0.0003468" ixz="-0.0003781" iyy="0.001062" iyz="-0.000558" izz="0.005716"/>
    </inertial>
  </link>
  <joint name="right_hip_joint" type="revolute">
    <parent link="right_hip_extension"/>
    <child link="right_upper_thigh"/>
    <origin rpy="1.5707963267948966 0.0 3.141592653589793" xyz="0.00933 0.0 0.0"/>
    <axis xyz="1 0 0"/>
    <limit effort="80.0" lower="-0.6981317007977318" upper="2.0943951023931953" velocity="3.0"/>
    <dynamics damping="2.0" friction="2.0"/>
  </joint>
  <!-- Fixed joint to add dummy inertia link -->
  <joint name="right_hip_joint_drive" type="continuous">
    <parent link="right_upper_thigh"/>
    <child link="right_upper_thigh_drive_inertia"/>
    <origin rpy="0 0 0" xyz="0 0 0"/>
    <axis xyz="-1 0 0"/>
    <limit effort="0.3265" velocity="367.5"/>
    <mimic joint="right_hip_joint" multiplier="0.0081632653"/>
  </joint>
  <visual>
    <origin rpy="0.0 0.0 0.0" xyz="0.0 0.0 0.0"/>
    <geometry>
      <box size="0.1 0.1 0.1"/>
    </geometry>
    <material name="red_mat">
      <color rgba="1 0 0 0.5"/>
    </material>
  </visual>
  <!-- Dummy inertia link, because KDL cannot have inertia on the base link -->
  <link name="right_upper_thigh_drive_inertia">
    <inertial>
      <origin rpy="0 0 0" xyz="0.0 0.0 0.0"/>
      <mass value="0.1"/>
      <inertia ixx="0.0001246" ixy="0.0" ixz="0.0" iyy="0.0001" iyz="0.0" izz="0.0001"/>
    </inertial>
  </link>
  <!-- Transmission tags for ros control -->
  <transmission name="{joint_name}_transmission">
    <type>transmission_interface/SimpleTransmission</type>
    <joint name="right_hip_joint">
      <hardwareInterface>hardware_interface/EffortJointInterface</hardwareInterface>
      <hardwareInterface>hardware_interface/PositionJointInterface</hardwareInterface>
      <hardwareInterface>hardware_interface/VelocityJointInterface</hardwareInterface>
    </joint>
    <actuator name="right_hip_joint_actuator">
      <hardwareInterface>hardware_interface/EffortJointInterface</hardwareInterface>
      <hardwareInterface>hardware_interface/PositionJointInterface</hardwareInterface>
      <hardwareInterface>hardware_interface/VelocityJointInterface</hardwareInterface>
      <mechanicalReduction>1</mechanicalReduction>
    </actuator>
  </transmission>
  <link name="right_upper_thigh_sensor"/>
  <joint name="right_upper_thigh_to_right_upper_thigh_sensor" type="fixed">
    <parent link="right_upper_thigh"/>
    <child link="right_upper_thigh_sensor"/>
    <origin rpy="3.141592653589793 0.0 0.0" xyz="-0.00369 -0.085 0.0"/>
  </joint>
  <link name="right_lower_thigh">
    <visual>
      <origin rpy="0 0 0" xyz="0 0 0"/>
      <geometry>
        <mesh filename="package://turtle_brick/knee-r.stl" scale="0.001   0.001   0.001"/>
      </geometry>
    </visual>
    <inertial>
      <origin rpy="0 0 0" xyz="-4e-05 0.05564 0.00411"/>
      <mass value="1.625"/>
      <inertia ixx="0.01096" ixy="5.38e-05" ixz="1.32e-05" iyy="0.001439" iyz="0.0003957" izz="0.01037"/>
    </inertial>
  </link>
  <joint name="fixed_right_upper_thigh_to_lower_thigh" type="fixed">
    <parent link="right_upper_thigh"/>
    <child link="right_lower_thigh"/>
    <origin rpy="0.0 3.141592653589793 0.0" xyz="-0.00313 -0.37 0.0"/>
  </joint>
  <link name="right_upper_shank">
    <visual>
      <origin rpy="0 0 0" xyz="0 0 0"/>
      <geometry>
        <mesh filename="package://turtle_brick/shank-r.stl" scale="0.001   0.001   0.001"/>
      </geometry>
    </visual>
    <inertial>
      <origin rpy="0 0 0" xyz="0.007566 -0.0908 0.00799"/>
      <mass value="0.5008"/>
      <inertia ixx="0.006507" ixy="-0.0003135" ixz="0.0002377" iyy="0.0007056" iyz="-0.0004257" izz="0.006426"/>
    </inertial>
  </link>
  <joint name="right_knee_joint" type="revolute">
    <parent link="right_lower_thigh"/>
    <child link="right_upper_shank"/>
    <origin rpy="0.0 0.0 0.0" xyz="0.01374 0.0 0.0"/>
    <axis xyz="-1 0 0"/>
    <limit effort="80.0" lower="-2.0943951023931953" upper="0.0" velocity="12.566370614359172"/>
    <dynamics damping="2.0" friction="2.0"/>
  </joint>
  <!-- Fixed joint to add dummy inertia link -->
  <joint name="right_knee_joint_drive" type="continuous">
    <parent link="right_upper_shank"/>
    <child link="right_upper_shank_drive_inertia"/>
    <origin rpy="0 0 0" xyz="0 0 0"/>
    <axis xyz="-1 0 0"/>
    <limit effort="0.3265" velocity="367.5"/>
    <mimic joint="right_knee_joint" multiplier="0.0081632653"/>
  </joint>
  <visual>
    <origin rpy="0.0 0.0 0.0" xyz="0.0 0.0 0.0"/>
    <geometry>
      <box size="0.1 0.1 0.1"/>
    </geometry>
    <material name="red_mat">
      <color rgba="1 0 0 0.5"/>
    </material>
  </visual>
  <!-- Dummy inertia link, because KDL cannot have inertia on the base link -->
  <link name="right_upper_shank_drive_inertia">
    <inertial>
      <origin rpy="0 0 0" xyz="0.0 0.0 0.0"/>
      <mass value="0.1"/>
      <inertia ixx="0.0001246" ixy="0.0" ixz="0.0" iyy="0.0001" iyz="0.0" izz="0.0001"/>
    </inertial>
  </link>
  <!-- Transmission tags for ros control -->
  <transmission name="{joint_name}_transmission">
    <type>transmission_interface/SimpleTransmission</type>
    <joint name="right_knee_joint">
      <hardwareInterface>hardware_interface/EffortJointInterface</hardwareInterface>
      <hardwareInterface>hardware_interface/PositionJointInterface</hardwareInterface>
      <hardwareInterface>hardware_interface/VelocityJointInterface</hardwareInterface>
    </joint>
    <actuator name="right_knee_joint_actuator">
      <hardwareInterface>hardware_interface/EffortJointInterface</hardwareInterface>
      <hardwareInterface>hardware_interface/PositionJointInterface</hardwareInterface>
      <hardwareInterface>hardware_interface/VelocityJointInterface</hardwareInterface>
      <mechanicalReduction>1</mechanicalReduction>
    </actuator>
  </transmission>
  <link name="right_upper_shank_sensor"/>
  <joint name="right_upper_shank_to_right_upper_shank_sensor" type="fixed">
    <parent link="right_upper_shank"/>
    <child link="right_upper_shank_sensor"/>
    <origin rpy="3.141592653589793 0.0 0.0" xyz="0.0019 -0.1 0.0"/>
  </joint>
  <link name="right_lower_shank">
    <visual>
      <origin rpy="0 0 0" xyz="0 0 0"/>
      <geometry>
        <mesh filename="package://turtle_brick/ankle.stl" scale="0.001   0.001   0.001"/>
      </geometry>
    </visual>
    <inertial>
      <origin rpy="0 0 0" xyz="-0.0009 -0.0 0.0562"/>
      <mass value="0.2802"/>
      <inertia ixx="0.001679" ixy="-0.0" ixz="0.0" iyy="0.001662" iyz="-0.0" izz="7.45e-05"/>
    </inertial>
  </link>
  <joint name="fixed_right_upper_shank_to_lower_shank" type="fixed">
    <parent link="right_upper_shank"/>
    <child link="right_lower_shank"/>
    <origin rpy="-1.5707963267948966 0.0 0.0" xyz="-0.006 -0.36 0.0"/>
  </joint>
  <link name="right_foot">
    <visual>
      <origin rpy="0 0 0" xyz="0 0 0"/>
      <geometry>
        <mesh filename="package://turtle_brick/foot-r.stl" scale="0.001   0.001   0.001"/>
      </geometry>
    </visual>
    <inertial>
      <origin rpy="0 0 0" xyz="0.0564 -0.02648 -0.08834"/>
      <mass value="0.8295"/>
      <inertia ixx="0.01149" ixy="-0.001746" ixz="-0.004842" iyy="0.01179" iyz="0.002451" izz="0.007927"/>
    </inertial>
  </link>
  <joint name="fixed_right_lower_shank_to_foot" type="fixed">
    <parent link="right_lower_shank"/>
    <child link="right_foot"/>
    <origin rpy="0.0 0.0 0.0" xyz="0.0 0.0 0.0"/>
  </joint>
  <!-- Ros control plugin
<gazebo>
  <plugin name="gazebo_ros_control" filename="libgazebo_ros_control.so">
    <robotNamespace>/x2</robotNamespace>
    <robotParam>$(arg robot_description_name)</robotParam>
  </plugin>
</gazebo> -->
  <!-- Modified Ros control plugin -->
  <gazebo>
    <plugin filename="libhwi_switch_gazebo_ros_control.so" name="gazebo_ros_control">
      <robotNamespace>x2</robotNamespace>
      <robotParam>x2/robot_description</robotParam>
    </plugin>
  </gazebo>
  <!-- Disable fixed point lumping
<gazebo reference="fixed_backpack_to_left_hip_ext">
  <disableFixedJointLumping>true</disableFixedJointLumping> 
  <preserveFixedJoint>true</preserveFixedJoint>
</gazebo>

<gazebo reference="fixed_left_upper_thigh_to_lower_thigh">
  <disableFixedJointLumping>true</disableFixedJointLumping> 
  <preserveFixedJoint>true</preserveFixedJoint>
</gazebo>

<gazebo reference="fixed_left_upper_shank_to_lower_shank">
  <disableFixedJointLumping>true</disableFixedJointLumping> 
  <preserveFixedJoint>true</preserveFixedJoint>
</gazebo>

<gazebo reference="fixed_left_lower_shank_to_foot">
  <disableFixedJointLumping>true</disableFixedJointLumping> 
  <preserveFixedJoint>true</preserveFixedJoint>
</gazebo>

<gazebo reference="fixed_backpack_to_right_hip_ext">
  <disableFixedJointLumping>true</disableFixedJointLumping> 
  <preserveFixedJoint>true</preserveFixedJoint>
</gazebo>


<gazebo reference="fixed_right_upper_thigh_to_lower_thigh">
  <disableFixedJointLumping>true</disableFixedJointLumping> 
  <preserveFixedJoint>true</preserveFixedJoint>
</gazebo>

<gazebo reference="fixed_right_upper_shank_to_lower_shank">
  <disableFixedJointLumping>true</disableFixedJointLumping> 
  <preserveFixedJoint>true</preserveFixedJoint>
</gazebo>

<gazebo reference="fixed_right_lower_shank_to_foot">
  <disableFixedJointLumping>true</disableFixedJointLumping> 
  <preserveFixedJoint>true</preserveFixedJoint>
</gazebo> -->
</robot>
